<?xml version="1.0" encoding="utf-8"?>
<robot name="sr7" xmlns:xacro="http://ros.org/wiki/xacro">
<!-- This URDF was automatically created by SolidWorks to URDF Exporter! Originally created by Stephen Brawner (brawner@gmail.com) 
     Commit Version: 1.5.1-0-g916b5db  Build Version: 1.5.7152.31018
     For more information, please see http://wiki.ros.org/sw_urdf_exporter -->
<robot
  name="mini_2">
  <link
    name="base_link">
    <inertial>
      <origin
        xyz="1.0574E-17 1.3878E-17 -0.047"
        rpy="0 0 0" />
      <mass
        value="4.4293" />
      <inertia
        ixx="0.017852"
        ixy="3.1098E-19"
        ixz="-6.5491E-20"
        iyy="0.013699"
        iyz="-7.4533E-22"
        izz="0.025667" />
    </inertial>
    <visual>
      <origin
        xyz="0 0 0"
        rpy="0 0 0" />
      <geometry>
        <mesh
          filename="package://mini_2/meshes/base_link.STL" />
      </geometry>
      <material
        name="">
        <color
          rgba="1 1 1 1" />
      </material>
    </visual>
    <collision>
      <origin
        xyz="0 0 0"
        rpy="0 0 0" />
      <geometry>
        <mesh
          filename="package://mini_2/meshes/base_link.STL" />
      </geometry>
    </collision>
  </link>
  <link
    name="LF">
    <inertial>
      <origin
        xyz="0.056718 0.00068841 1.2544E-08"
        rpy="0 0 0" />
      <mass
        value="0.18919" />
      <inertia
        ixx="0.00010953"
        ixy="-4.922E-07"
        ixz="7.0037E-11"
        iyy="0.00023572"
        iyz="1.0721E-10"
        izz="0.00014878" />
    </inertial>
    <visual>
      <origin
        xyz="0 0 0"
        rpy="0 0 0" />
      <geometry>
        <mesh
          filename="package://mini_2/meshes/LF.STL" />
      </geometry>
      <material
        name="">
        <color
          rgba="1 1 1 1" />
      </material>
    </visual>
    <collision>
      <origin
        xyz="0 0 0"
        rpy="0 0 0" />
      <geometry>
        <mesh
          filename="package://mini_2/meshes/LF.STL" />
      </geometry>
    </collision>
  </link>
  <joint
    name="abad_1"
    type="continuous">
    <origin
      xyz="-0.05 0.1355 -0.047"
      rpy="3.1416 0 1.5708" />
    <parent
      link="base_link" />
    <child
      link="LF" />
    <axis
      xyz="1 0 0" />
    <limit lower = "-3.14" upper = "3.14" effort = "120.0" velocity = "3.15"/>
  </joint>
  <link
    name="big_leg_lf">
    <inertial>
      <origin
        xyz="0.0085726 -0.020206 0.035216"
        rpy="0 0 0" />
      <mass
        value="0.32751" />
      <inertia
        ixx="0.0015066"
        ixy="2.7645E-05"
        ixz="-4.8182E-05"
        iyy="0.0011556"
        iyz="0.00054818"
        izz="0.00051477" />
    </inertial>
    <visual>
      <origin
        xyz="0 0 0"
        rpy="0 0 0" />
      <geometry>
        <mesh
          filename="package://mini_2/meshes/big_leg_lf.STL" />
      </geometry>
      <material
        name="">
        <color
          rgba="1 1 1 1" />
      </material>
    </visual>
    <collision>
      <origin
        xyz="0 0 0"
        rpy="0 0 0" />
      <geometry>
        <mesh
          filename="package://mini_2/meshes/big_leg_lf.STL" />
      </geometry>
    </collision>
  </link>
  <joint
    name="hip_1"
    type="continuous">
    <origin
      xyz="0.0605 -0.0643 0"
      rpy="0 0 -1.5708" />
    <parent
      link="LF" />
    <child
      link="big_leg_lf" />
    <axis
      xyz="1 0 0" />
    <limit lower="0" upper="3.14" effort="120.0" velocity="3.15"/>
  </joint>
  <link
    name="small_leg_lf">
    <inertial>
      <origin
        xyz="0 0.0898073159376234 0.106766263255926"
        rpy="0 0 0" />
      <mass
        value="0.127491467510119" />
      <inertia
        ixx="0.000844635378320729"
        ixy="-5.99313665689285E-20"
        ixz="-7.44217417646053E-20"
        iyy="0.000501706578256797"
        iyz="-0.000403362453730493"
        izz="0.000361465982896823" />
    </inertial>
    <visual>
      <origin
        xyz="0 0 0"
        rpy="0 0 0" />
      <geometry>
        <mesh
          filename="package://mini_2/meshes/small_leg_lf.STL" />
      </geometry>
      <material
        name="">
        <color
          rgba="1 1 1 1" />
      </material>
    </visual>
    <collision>
      <origin
        xyz="0 0 0"
        rpy="0 0 0" />
      <geometry>
        <mesh
          filename="package://mini_2/meshes/small_leg_lf.STL" />
      </geometry>
    </collision>
  </link>
  <joint
    name="knee_1"
    type="continuous">
    <origin
      xyz="0.01275 -0.10451 0.18215"
      rpy="0 0 0" />
    <parent
      link="big_leg_lf" />
    <child
      link="small_leg_lf" />
    <axis
      xyz="1 0 0" />
    <limit lower="0" upper="1.5" effort="120.0" velocity="3.15"/>
  </joint>
  <link
    name="RF">
    <inertial>
      <origin
        xyz="0.000688407309070764 0.0567179690053556 -1.25439409380534E-08"
        rpy="0 0 0" />
      <mass
        value="0.189190508294776" />
      <inertia
        ixx="0.00023571914650583"
        ixy="-4.92200150260086E-07"
        ixz="-1.07211218923642E-10"
        iyy="0.00010953071228249"
        iyz="-7.0036949810941E-11"
        izz="0.000148779257271577" />
    </inertial>
    <visual>
      <origin
        xyz="0 0 0"
        rpy="0 0 0" />
      <geometry>
        <mesh
          filename="package://mini_2/meshes/RF.STL" />
      </geometry>
      <material
        name="">
        <color
          rgba="1 1 1 1" />
      </material>
    </visual>
    <collision>
      <origin
        xyz="0 0 0"
        rpy="0 0 0" />
      <geometry>
        <mesh
          filename="package://mini_2/meshes/RF.STL" />
      </geometry>
    </collision>
  </link>
  <joint
    name="abad_2"
    type="continuous">
    <origin
      xyz="0.05 0.1355 -0.047"
      rpy="3.1416 0 3.1416" />
    <parent
      link="base_link" />
    <child
      link="RF" />
    <axis
      xyz="0 1 0" />
    <limit lower="-3.14" upper="3.14" effort="120.0" velocity="3.15"/>
  </joint>
  <link
    name="big_leg_rf">
    <inertial>
      <origin
        xyz="-0.00857255217752802 -0.0153640092159915 0.0375822825992731"
        rpy="0 0 0" />
      <mass
        value="0.327511116196439" />
      <inertia
        ixx="0.00150657307795071"
        ixy="-2.10204320549148E-05"
        ixz="5.14185982799571E-05"
        iyy="0.00128832642740156"
        iyz="0.000444820196934176"
        izz="0.000382087652364959" />
    </inertial>
    <visual>
      <origin
        xyz="0 0 0"
        rpy="0 0 0" />
      <geometry>
        <mesh
          filename="package://mini_2/meshes/big_leg_rf.STL" />
      </geometry>
      <material
        name="">
        <color
          rgba="1 1 1 1" />
      </material>
    </visual>
    <collision>
      <origin
        xyz="0 0 0"
        rpy="0 0 0" />
      <geometry>
        <mesh
          filename="package://mini_2/meshes/big_leg_rf.STL" />
      </geometry>
    </collision>
  </link>
  <joint
    name="hip_2"
    type="continuous">
    <origin
      xyz="-0.0643 0.0605 0"
      rpy="0 0 0" />
    <parent
      link="RF" />
    <child
      link="big_leg_rf" />
    <axis
      xyz="-1 0 0" />
    <limit lower="-3.14" upper="3.14" effort="120.0" velocity="3.15"/>
  </joint>
  <link
    name="small_leg_rf">
    <inertial>
      <origin
        xyz="-2.77555756156289E-17 0.0951163761413282 0.102064998678759"
        rpy="0 0 0" />
      <mass
        value="0.127491467510119" />
      <inertia
        ixx="0.00084463537832073"
        ixy="7.30721652165356E-20"
        ixz="6.13830133689104E-20"
        iyy="0.000460405640151544"
        iyz="-0.000408396339038337"
        izz="0.000402766921002077" />
    </inertial>
    <visual>
      <origin
        xyz="0 0 0"
        rpy="0 0 0" />
      <geometry>
        <mesh
          filename="package://mini_2/meshes/small_leg_rf.STL" />
      </geometry>
      <material
        name="">
        <color
          rgba="1 1 1 1" />
      </material>
    </visual>
    <collision>
      <origin
        xyz="0 0 0"
        rpy="0 0 0" />
      <geometry>
        <mesh
          filename="package://mini_2/meshes/small_leg_rf.STL" />
      </geometry>
    </collision>
  </link>
  <joint
    name="knee_2"
    type="continuous">
    <origin
      xyz="-0.0127500000000001 -0.0794661027406418 0.194383997580083"
      rpy="0 0 0" />
    <parent
      link="big_leg_rf" />
    <child
      link="small_leg_rf" />
    <axis
      xyz="-1 0 0" />
    <limit
      lower="0"
      upper="1.5"
      effort="120"
      velocity="3.15" />
  </joint>
  <link
    name="LB">
    <inertial>
      <origin
        xyz="-0.000688407309070896 -0.0567179690053556 -1.25439408825423E-08"
        rpy="0 0 0" />
      <mass
        value="0.189190508294776" />
      <inertia
        ixx="0.00023571914650583"
        ixy="-4.92200150260094E-07"
        ixz="1.07211218978578E-10"
        iyy="0.000109530712282491"
        iyz="7.00369498248643E-11"
        izz="0.000148779257271578" />
    </inertial>
    <visual>
      <origin
        xyz="0 0 0"
        rpy="0 0 0" />
      <geometry>
        <mesh
          filename="package://mini_2/meshes/LB.STL" />
      </geometry>
      <material
        name="">
        <color
          rgba="1 1 1 1" />
      </material>
    </visual>
    <collision>
      <origin
        xyz="0 0 0"
        rpy="0 0 0" />
      <geometry>
        <mesh
          filename="package://mini_2/meshes/LB.STL" />
      </geometry>
    </collision>
  </link>
  <joint
    name="abad_3"
    type="continuous">
    <origin
      xyz="-0.0499999999999999 -0.1355 -0.047"
      rpy="3.14159265358979 0 3.14159265358979" />
    <parent
      link="base_link" />
    <child
      link="LB" />
    <axis
      xyz="0 -1 0" />
    <limit lower="-3.14" upper="3.14" effort="120.0" velocity="3.15"/>
  </joint>
  <link
    name="big_leg_lb">
    <inertial>
      <origin
        xyz="0.00857255217752802 -0.0240353186595707 0.0327228391416993"
        rpy="0 0 0" />
      <mass
        value="0.327511116196439" />
      <inertia
        ixx="0.00150657307795071"
        ixy="3.28841759790063E-05"
        ixz="-4.47700992073125E-05"
        iyy="0.00102513588265668"
        iyz="0.00060589538835369"
        izz="0.000645278197109841" />
    </inertial>
    <visual>
      <origin
        xyz="0 0 0"
        rpy="0 0 0" />
      <geometry>
        <mesh
          filename="package://mini_2/meshes/big_leg_lb.STL" />
      </geometry>
      <material
        name="">
        <color
          rgba="1 1 1 1" />
      </material>
    </visual>
    <collision>
      <origin
        xyz="0 0 0"
        rpy="0 0 0" />
      <geometry>
        <mesh
          filename="package://mini_2/meshes/big_leg_lb.STL" />
      </geometry>
    </collision>
  </link>
  <joint
    name="hip_3"
    type="continuous">
    <origin
      xyz="0.0643 -0.0605000000000013 0"
      rpy="0 0 0" />
    <parent
      link="LB" />
    <child
      link="big_leg_lb" />
    <axis
      xyz="1 0 0" />
    <limit lower="-3.14" upper="3.14" effort="120.0" velocity="3.15"/>
  </joint>
  <link
    name="small_leg_lb">
    <inertial>
      <origin
        xyz="-2.77555756156289E-17 0.108972165187923 0.087117484925873"
        rpy="0 0 0" />
      <mass
        value="0.127491467510119" />
      <inertia
        ixx="0.00084463537832073"
        ixy="1.40170611498597E-19"
        ixz="1.07495027940306E-19"
        iyy="0.000341446012903266"
        iyz="-0.000399365568583417"
        izz="0.000521726548250354" />
    </inertial>
    <visual>
      <origin
        xyz="0 0 0"
        rpy="0 0 0" />
      <geometry>
        <mesh
          filename="package://mini_2/meshes/small_leg_lb.STL" />
      </geometry>
      <material
        name="">
        <color
          rgba="1 1 1 1" />
      </material>
    </visual>
    <collision>
      <origin
        xyz="0 0 0"
        rpy="0 0 0" />
      <geometry>
        <mesh
          filename="package://mini_2/meshes/small_leg_lb.STL" />
      </geometry>
    </collision>
  </link>
  <joint
    name="knee_3"
    type="continuous">
    <origin
      xyz="0.0127500000000002 -0.12431606068145 0.169249865750747"
      rpy="0 0 0" />
    <parent
      link="big_leg_lb" />
    <child
      link="small_leg_lb" />
    <axis
      xyz="-1 0 0" />
    <limit lower="0" upper="1.5" effort="120.0" velocity="3.15"/>
  </joint>
  <link
    name="RB">
    <inertial>
      <origin
        xyz="0.000688407309071118 -0.0567179690053556 1.25439408305006E-08"
        rpy="0 0 0" />
      <mass
        value="0.189190508294776" />
      <inertia
        ixx="0.00023571914650583"
        ixy="4.9220015026008E-07"
        ixz="1.07211218983504E-10"
        iyy="0.00010953071228249"
        iyz="-7.0036949824629E-11"
        izz="0.000148779257271577" />
    </inertial>
    <visual>
      <origin
        xyz="0 0 0"
        rpy="0 0 0" />
      <geometry>
        <mesh
          filename="package://mini_2/meshes/RB.STL" />
      </geometry>
      <material
        name="">
        <color
          rgba="1 1 1 1" />
      </material>
    </visual>
    <collision>
      <origin
        xyz="0 0 0"
        rpy="0 0 0" />
      <geometry>
        <mesh
          filename="package://mini_2/meshes/RB.STL" />
      </geometry>
    </collision>
  </link>
  <joint
    name="abad_4"
    type="continuous">
    <origin
      xyz="0.0500000000000002 -0.1355 -0.0469999999999999"
      rpy="3.14159265358979 0 3.14159265358979" />
    <parent
      link="base_link" />
    <child
      link="RB" />
    <axis
      xyz="0 -1 0" />
    <limit lower="-3.14" upper="3.14" effort="120.0" velocity="3.15"/>
  </joint>
  <link
    name="big_leg_rb">
    <inertial>
      <origin
        xyz="-0.00857255217752814 -0.0195048014934553 0.0356095979092968"
        rpy="0 0 0" />
      <mass
        value="0.327511116196439" />
      <inertia
        ixx="0.00150657307795072"
        ixy="-2.66857008983709E-05"
        ixz="4.87196488125004E-05"
        iyy="0.00117709759848427"
        iyz="0.000535063578357767"
        izz="0.000493316481282268" />
    </inertial>
    <visual>
      <origin
        xyz="0 0 0"
        rpy="0 0 0" />
      <geometry>
        <mesh
          filename="package://mini_2/meshes/big_leg_rb.STL" />
      </geometry>
      <material
        name="">
        <color
          rgba="1 1 1 1" />
      </material>
    </visual>
    <collision>
      <origin
        xyz="0 0 0"
        rpy="0 0 0" />
      <geometry>
        <mesh
          filename="package://mini_2/meshes/big_leg_rb.STL" />
      </geometry>
    </collision>
  </link>
  <joint
    name="hip_4"
    type="continuous">
    <origin
      xyz="-0.0642999999999996 -0.0604999999999999 0"
      rpy="0 0 0" />
    <parent
      link="RB" />
    <child
      link="big_leg_rb" />
    <axis
      xyz="-1 0 0" />
   <limit lower="-3.14" upper="3.14" effort="120.0" velocity="3.15"/>
  </joint>
  <link
    name="small_leg_rb">
    <inertial>
      <origin
        xyz="-1.1102E-16 0.074661 0.11786"
        rpy="0 0 0" />
      <mass
        value="0.12749" />
      <inertia
        ixx="0.00084464"
        ixy="1.2816E-19"
        ixz="2.0474E-19"
        iyy="0.0006065"
        iyz="-0.00037017"
        izz="0.00025667" />
    </inertial>
    <visual>
      <origin
        xyz="0 0 0"
        rpy="0 0 0" />
      <geometry>
        <mesh
          filename="package://mini_2/meshes/small_leg_rb.STL" />
      </geometry>
      <material
        name="">
        <color
          rgba="1 1 1 1" />
      </material>
    </visual>
    <collision>
      <origin
        xyz="0 0 0"
        rpy="0 0 0" />
      <geometry>
        <mesh
          filename="package://mini_2/meshes/small_leg_rb.STL" />
      </geometry>
    </collision>
  </link>
  <joint
    name="knee_4"
    type="continuous">
    <origin
      xyz="-0.01275 -0.10088 0.18418"
      rpy="0 0 0" />
    <parent
      link="big_leg_rb" />
    <child
      link="small_leg_rb" />
    <axis
      xyz="-1 0 0" />
    <limit lower="0" upper="1.5" effort="120.0" velocity="3.15"/>
  </joint>
</robot>
